Workbook

Sheet Orçam-Realiza
B1: AGROINVEST | C1: AGROINVEST | D1: AGROINVEST | E1: AGROINVEST | F1: AGROINVEST | G1: AGROINVEST | H1: AGROINVEST | I1: AGROINVEST | J1: AGROINVEST
B2: 2025-2026 (01 Outubro - 30 Setembro) | C2: 2025-2026 (01 Outubro - 30 Setembro) | D2: 2025-2026 (01 Outubro - 30 Setembro) | E2: 2025-2026 (01 Outubro - 30 Setembro) | F2: 2025-2026 (01 Outubro - 30 Setembro) | G2: 2025-2026 (01 Outubro - 30 Setembro) | H2: 2025-2026 (01 Outubro - 30 Setembro) | I2: 2025-2026 (01 Outubro - 30 Setembro) | J2: 2025-2026 (01 Outubro - 30 Setembro) | AB2: =$AB$16+(AD2*$AB$19) | AD2: 1.2
B3: Fatores Importantes : | AB3: =$AB$16+(AD3*$AB$19) | AD3: 1.15
D4: Algodão | F4: Soja | H4: Milho | J4: Caroço | L4: Total | AB4: =$AB$16+(AD4*$AB$19) | AD4: 1.1
C5: Hectares de Produção (todas fazendas) | D5: 0 | F5: 900 | H5: 1380 | J5: N/A | L5: =D5+F5+H5 | AB5: =$AB$16+(AD5*$AB$19) | AD5: 1.05
D6: =D5/$L5 | F6: =F5/$L5 | H6: =H5/$L5 | L6: =SUM(D6:K6) | AB6: =D80 | AD6: 1 | AE6: = 100% Metas / Bonus / 70% salario bruta
C7: Hectares de Produção (parte de CF) | D7: 0 | F7: =F5 | G7: 5750 | H7: =H5 | J7: N/A | L7: =D7+F7+H7 | M7: Produtividade reducao: | AB7: =$AB$16+(AD7*$AB$19) | AD7: 0.9
C8: (Carroll, mais de um terço das outras fazendas) | D8: =D7/$L7 | F8: =F7/$L7 | H8: =H7/$L7 | L8: =SUM(D8:K8) | AA8: 0 | AB8: =$AB$16+(AD8*$AB$19) | AD8: 0.75
AA9: =AB6-AA10 | AB9: =$AB$16+(AD9*$AB$19) | AD9: 0.65
C10: Pressupostos de Produção | D10: 0 | F10: 70 | H10: 180 | J10: N/A | M10: Resultado: (realizado orçamento) | AB10: =$AB$16+(AD10*$AB$19) | AD10: 0.5
D11: Arrobas/HA | F11: Sacas/HA | H11: Sacas/HA | M11: Receita algodao | AA11: =D43 | AB11: =$AB$16+(AD11*$AB$19) | AD11: 0.4
M12: Receita milho | AA12: =D45 | AB12: =$AB$16+(AD12*$AB$19) | AD12: 0.25
C13: Os Preços-Alvo - USD | D13: 0 | F13: 20 | H13: =60/D29 | M13: Receita soja | P13: Total Arrobas: | Q13: 465439.97 | AA13: =D44 | AB13: =$AB$16+(AD13*$AB$19) | AD13: 0.2
C14: (Vamos utilizar o preço médio de venda fixo para produção total) | D14: Por lb | F14: Por Saca | H14: Por Saca | J14: Por tonelada | P14: Total Kilos: | Q14: =Q13*15 | AB14: =$AB$16+(AD14*$AB$19) | AD14: 0.15
C15: (Vamos utilizar o preço médio de venda fixo para produção total) | P15: Total Pounds: | Q15: =Q14/0.45359237 | AB15: =$AB$16+(AD15*$AB$19) | AD15: 0.1
C16: Os Preços-Alvo - BRL | D16: =D13*2.2046*D29*15 | F16: =F13*D29 | H16: =H13*D29 | J16: =J13*D29 | P16: Total Reais: | Q16: =Q15*D13*D29 | AB16: 1813938 | AD16: 0
D17: Por Arroba | F17: Por Saca | H17: Por Saca | J17: Por tonelada | P17: Check: | Q17: =Q16-D43
C19: Custo do descaroçamento por arroba pluma | D19: 8.25 | AB19: =AB6-AB16
AB20: =1-(AA9/AB19) | AC20: =(AC21*AB20)/AB21 | AD20: Meta
C21: Percentual vendidos no Pessoa Juridica | D21: 1 | F21: =D19-F19 | AB21: 100 | AC21: 70
C22: Percentual da algodão exportado | D22: 1
C23: Percentual da soja e milho vendidos na Bahia | D23: 1
C24: Percentual da caroço vendidos para indústria | D24: 1
C26: Pluma Percentuais | D26: 0.4 | J26: 0.52
C28: Subsídios | D28: 0
C29: Taxa de câmbio (R$ por USD) | D29: 5.4 | F29: BRL/USD
C32: Em EUA dolares $$ por hectare | D32: =D35 | F32: =F35 | H32: =H35
C33: Custo defensivos, adubo, e semente - 24/25 | D33: 0 | F33: ='Quimi. Fert. Semente'!G27 | H33: ='Quimi. Fert. Semente'!G28
D34: 0 | F34: =(F33*D29)-F36 | H34: =(H33*D29)-H36
C35: Em BR reais R$ por hectare | D35: =D4 | F35: =F4 | H35: =H4
C36: Custo projetado de produção 25-26 | D36: 0 | F36: ='Quimi. Fert. Semente'!G22*'Orçam-Realiza'!D29 | H36: ='Quimi. Fert. Semente'!G23*'Orçam-Realiza'!D29
C37: Custo do ano anterior de produção - 2024 | D37: 0 | F37: =F33*D29 | H37: =H33*D29
O39: Algodão | Q39: Soja | S39: Milho
D40: 2025 - 2026 Safra | O40: 3801.3676 | P40: =O40/Q40 | Q40: 1154.5599 | S40: 1647.2279
F41: Percentual da | O41: =D5 | Q41: =F5 | S41: =H5
D42: BRL$ | F42: Receitas
C43: Vendas de algodão | D43: =D16*D10*D26*(D7+H43) | F43: =D43/$D$48
C44: Vendas de soja | D44: =F16*F10*F7 | F44: =D44/$D$48 | O44: 10327 | Q44: 392 | S44: 691
C45: Vendas de milho | D45: =H16*H10*H7 | F45: =D45/$D$48
B46: RECEITAS | C46: Vendas de caroço | D46: =(D10*D7*J26*15)/1000*J16 | F46: =D46/$D$48
...

Sheet Orçamento Resumo
A1: ORÇAMENTO 22-23 | B1: ORÇAMENTO 22-23 | C1: ORÇAMENTO 22-23 | D1: ORÇAMENTO 22-23 | E1: ORÇAMENTO 22-23
B2: DIESEL | C2: Gasolina | D2: Lubrificantes | E2: Peças e concertos | F2: Silo bolsa | G2: Veiculos | H2: Aluguel de carro/trator | I2: Suprimentos | J2: Serviços Proficionais | K2: Salarios, Provisões e Encargos | L2: Avião | M2: Contratação Serviços | N2: Seguros | O2: Utilidades Fazenda | P2: Alimentos | Q2: Fertilizante | R2: Quimicos | S2: Semente
A3: Outubro | B3: ='Combust. Lubrif'!$D$27*0.09 | C3: ='Combust. Lubrif'!$K$3/12 | D3: ='Combust. Lubrif'!L23/12 | E3: ='peças '!C28 | I3: ='Supriment-Ser Profiss'!$C$96/12 | J3: ='Supriment-Ser Profiss'!$H$82/12 | K3: ='Folha pagamento '!N24/14 | N3: 96000 | O3: ='Utilidades e Veiculos'!P3 | P3: ='Alimentação '!E85 | T3: =SUM(B3:S3)
A4: Novembro | B4: ='Combust. Lubrif'!$D$27*0.09 | C4: ='Combust. Lubrif'!$K$3/12 | D4: ='Combust. Lubrif'!L23/12 | E4: ='peças '!D28 | I4: ='Supriment-Ser Profiss'!$C$96/12 | J4: ='Supriment-Ser Profiss'!$H$82/12 | K4: ='Folha pagamento '!N24/14+'Folha pagamento '!N29 | O4: ='Utilidades e Veiculos'!P4 | P4: ='Alimentação '!G85 | T4: =SUM(B4:S4)
A5: Dezembro | B5: ='Combust. Lubrif'!$D$27*0.09 | C5: ='Combust. Lubrif'!$K$3/12 | D5: ='Combust. Lubrif'!L23/12 | E5: ='peças '!E28 | I5: ='Supriment-Ser Profiss'!$C$96/12 | J5: ='Supriment-Ser Profiss'!$H$82/12 | K5: ='Folha pagamento '!N24/14+'Folha pagamento '!N29 | L5: =Avião!$Q$99/5 | O5: ='Utilidades e Veiculos'!P5 | P5: ='Alimentação '!I85 | T5: =SUM(B5:S5)
A6: Janeiro | B6: ='Combust. Lubrif'!D27*0.1 | C6: ='Combust. Lubrif'!$K$3/12 | D6: ='Combust. Lubrif'!L23/12 | E6: ='peças '!F28 | G6: ='Utilidades e Veiculos'!H63 | I6: ='Supriment-Ser Profiss'!$C$96/12 | J6: ='Supriment-Ser Profiss'!$H$82/12 | K6: ='Folha pagamento '!N24/14 | L6: =Avião!$Q$99/5 | O6: ='Utilidades e Veiculos'!P6 | P6: ='Alimentação '!K85 | T6: =SUM(B6:S6)
A7: Fevereiro | B7: ='Combust. Lubrif'!D27*0.1 | C7: ='Combust. Lubrif'!$K$3/12 | D7: ='Combust. Lubrif'!L23/12 | E7: ='peças '!G28 | F7: ='Contratação serviç.'!I17/3 | I7: ='Supriment-Ser Profiss'!$C$96/12 | J7: ='Supriment-Ser Profiss'!$H$82/12 | K7: ='Folha pagamento '!N24/14 | L7: =Avião!$Q$99/5 | O7: ='Utilidades e Veiculos'!P7 | P7: ='Alimentação '!M85 | T7: =SUM(B7:S7)
A8: Março | B8: ='Combust. Lubrif'!D27*0.11 | C8: ='Combust. Lubrif'!$K$3/12 | D8: ='Combust. Lubrif'!L23/12 | E8: ='peças '!H28 | F8: ='Contratação serviç.'!I17/3 | I8: ='Supriment-Ser Profiss'!$C$96/12 | J8: ='Supriment-Ser Profiss'!$H$82/12 | K8: ='Folha pagamento '!N24/14+'Folha pagamento '!N29 | L8: =Avião!$Q$99/5 | M8: ='Contratação serviç.'!$B$19/3 | O8: ='Utilidades e Veiculos'!P8 | P8: ='Alimentação '!O85 | T8: =SUM(B8:S8)
A9: Abril | B9: ='Combust. Lubrif'!D27*0.11 | C9: ='Combust. Lubrif'!$K$3/12 | D9: ='Combust. Lubrif'!L23/12 | E9: ='peças '!I28 | F9: ='Contratação serviç.'!I17/3 | I9: ='Supriment-Ser Profiss'!$C$96/12 | J9: ='Supriment-Ser Profiss'!$H$82/12 | K9: ='Folha pagamento '!N24/14 | L9: =Avião!$Q$99/5 | M9: ='Contratação serviç.'!$B$19/3 | O9: ='Utilidades e Veiculos'!P9 | P9: ='Alimentação '!Q85 | T9: =SUM(B9:S9)
A10: Maio | B10: ='Combust. Lubrif'!D27*0.11 | C10: ='Combust. Lubrif'!$K$3/12 | D10: ='Combust. Lubrif'!L23/12 | E10: ='peças '!J28 | I10: ='Supriment-Ser Profiss'!$C$96/12 | J10: ='Supriment-Ser Profiss'!$H$82/12 | K10: ='Folha pagamento '!N24/14 | M10: ='Contratação serviç.'!$B$19/3 | O10: ='Utilidades e Veiculos'!P10 | P10: ='Alimentação '!S85 | T10: =SUM(B10:S10)
A11: Junho | B11: ='Combust. Lubrif'!D27*0.07 | C11: ='Combust. Lubrif'!$K$3/12 | D11: ='Combust. Lubrif'!L23/12 | E11: ='peças '!K28 | I11: ='Supriment-Ser Profiss'!$C$96/12 | J11: ='Supriment-Ser Profiss'!$H$82/12 | K11: ='Folha pagamento '!N24/14 | O11: ='Utilidades e Veiculos'!P11 | P11: ='Alimentação '!U85 | T11: =SUM(B11:S11)
A12: Julho | B12: ='Combust. Lubrif'!D27*0.07 | C12: ='Combust. Lubrif'!$K$3/12 | D12: ='Combust. Lubrif'!L23/12 | E12: ='peças '!L28 | I12: ='Supriment-Ser Profiss'!$C$96/12 | J12: ='Supriment-Ser Profiss'!$H$82/12 | K12: ='Folha pagamento '!N24/14 | O12: ='Utilidades e Veiculos'!P12 | P12: ='Alimentação '!W85 | T12: =SUM(B12:S12)
A13: Agosto | B13: ='Combust. Lubrif'!D27*0.03 | C13: ='Combust. Lubrif'!$K$3/12 | D13: ='Combust. Lubrif'!L23/12 | E13: ='peças '!M28 | I13: ='Supriment-Ser Profiss'!$C$96/12 | J13: ='Supriment-Ser Profiss'!$H$82/12 | K13: ='Folha pagamento '!N24/14 | O13: ='Utilidades e Veiculos'!P13 | P13: ='Alimentação '!Y85 | T13: =SUM(B13:S13) | V13: U$$/há
A14: Setembro | B14: ='Combust. Lubrif'!D27*0.03 | C14: ='Combust. Lubrif'!$K$3/12 | D14: ='Combust. Lubrif'!L23/12 | E14: ='peças '!N28 | I14: ='Supriment-Ser Profiss'!$C$96/12 | J14: ='Supriment-Ser Profiss'!$H$82/12 | K14: ='Folha pagamento '!N24/14+'Folha pagamento '!N29 | O14: ='Utilidades e Veiculos'!P14 | P14: ='Alimentação '!AA85 | T14: =SUM(B14:S14) | U14: =U15/2300 | V14: =U14/5.6
A15: Total | B15: =SUM(B3:B14) | C15: =SUM(C3:C14) | D15: =SUM(D3:D14) | E15: =SUM(E3:E14) | F15: =SUM(F3:F14) | G15: =SUM(G3:G14) | H15: =SUM(H3:H14) | I15: =SUM(I3:I14) | ... P15: =SUM(P3:P14) | Q15: ='Quimi. Fert. Semente'!N10 | R15: ='Quimi. Fert. Semente'!I15 | S15: ='Quimi. Fert. Semente'!D15 | T15: =SUM(B15:S15) | U15: =SUM(B15:P15)+1282000
A17: 24-25 | B17: 873061 | C17: 873061 | D17: 873061 | E17: 767995 | F17: 16516 | G17: 8733 | H17: 4646 | I17: 142786 | J17: 812270 | K17: 995123 | L17: 410999 | M17: 871101 | N17: 94566 | O17: 83550 | P17: 196587 | Q17: 2758778.5 | R17: 2067511.2 | S17: 1511168.3 | T17: 10986279 | U17: 5930820.7
A18: Realizado 23-24 | B18: 700501.45 | C18: 700501.45 | D18: 700501.45 | E18: 687314.62 | F18: 17629.37 | G18: 7284.81 | H18: 0 | I18: 97114.28 | J18: 644446.82 | K18: 896802.99 | L18: -271514.77 | M18: 1022660.5 | N18: 69423.5 | O18: 104331.61 | P18: 165702.01 | Q18: 2424711 | R18: 2483600 | S18: 2042476 | T18: =SUM(B18:S18) | U18: =SUM(B18:P18) | V18: =(T15/T21)-1
A19: Realizado 23-24 | B19: 1007230 | C19: 1007230 | D19: 1007230 | E19: 442901.09 | F19: 11440 | G19: 7497.47 | H19: 0 | I19: 133422 | J19: 907493.23 | K19: 714449.57 | L19: 332262.36 | M19: 1063200 | N19: 33859.32 | O19: 137089.96 | P19: 152681.36 | Q19: 2122830 | R19: 1812595 | S19: 1829700 | T19: =SUM(B19:S19)
A20: Realizado 22-23 | B20: 1072358 | C20: 1072358 | D20: 1072358 | E20: 816622 | F20: 95121 | G20: 5660 | H20: 109000 | I20: 160587 | J20: 395630 | K20: 1065858 | L20: 335462 | M20: 2866224 | O20: 184570 | P20: 254116
A21: Realizado 21-22 | B21: 1717934 | C21: 1717934 | D21: 1717934 | E21: 960925 | F21: 188221 | G21: 9150 | H21: 43707 | I21: 71842 | J21: 298686 | K21: 1003922 | L21: 216259 | M21: 2667281 | O21: 153895 | P21: 225555 | Q21: 4537127 | R21: 5666912 | S21: 2825189 | T21: =SUM(B21:S21)
A22: Realizado 20-21 | B22: 578356.23 | C22: 578356.23 | D22: 578356.23 | E22: 162336.64 | F22: 53067.13 | G22: 5046.22 | H22: 0 | I22: 56679.488 | J22: 242050.96 | K22: 661110.68 | L22: 305977.24 | M22: 2178115 | N22: 0 | O22: 86875 | P22: 99000 | Q22: 0 | R22: 4849531 | S22: 2171360 | T22: =SUM(B22:S22)
A25: custo/há orçado | B25: =B15:D15/2300 | C25: =B15:D15/2300 | D25: =B15:D15/2300 | E25: =E15/2300 | F25: =F15/2300 | G25: =G15/2300 | H25: =H15/2300 | I25: =I15/2300 | J25: =J15/2300 | K25: =K15/2300 | L25: =L15/2300 | ... P25: =P15/2300
A27: Custo/há realizado | B27: =B17/2300 | C27: =B17/2300 | D27: =B17/2300 | E27: =E17/2300 | F27: =F17/2300 | G27: =G17/2300 | H27: =H17/2300 | I27: =I17/2300 | J27: =J17/2300 | K27: =K17/2300 | L27: =L17/2300 | ... P27: =P17/2300
G31: =SUM(C8,H8,M6) | H31: 888 | J31: =I31*5.2
I32: =SUM(I27:I31) | J32: =SUM(J27:J31)
G34: 347.57 | H34: 4127 | O34: =SUM(B15:P15)/2300
G35: 667.19 | H35: 1642 | O35: =O34/5.4

Sheet Combust. Lubrif
A1: Operação | B1: Media | C1: hectar/KM/hora | D1: total diesel | G1: Lubrificantes e Combustiveis
A2: Colheita Soja | B2: 13 | C2: 900 | D2: =C2*B2
A3: colheita milho | B3: 14 | C3: 1380 | D3: =C3*B3 | G3: Gasolina | H3: lts | I3: 6.4 | J3: 1300 | K3: =SUM(J3*I3)
A4: Colheita sementes cobertura | B4: 7 | C4: 200 | D4: =C4*B4
A5: Colheita de sorgo | B5: 8 | C5: 500 | D5: =C5*B5 | G5: Oleo 20w50 moto | H5: lts | I5: 26 | J5: 12 | K5: =SUM(J5*I5)
A6: Plantio Soja | B6: 4.57 | C6: 900 | D6: =B6*C6
A7: Plantio Milho | B7: 5 | C7: 1380 | D7: =C7*B7 | G7: graxa mineral | H7: Kgs | I7: 30 | J7: 60 | K7: =SUM(J7*I7)
A8: Plantio braquiaria | B8: 1.63 | C8: 1380 | D8: =C8*B8 | G8: Oleo plus 50 II | H8: lts | I8: 37 | J8: 60 | K8: =SUM(J8*I8)
A9: preparo de solo | B9: 20 | C9: 900 | D9: =C9*B9 | G9: Oleo 85w140 cubo | H9: lts | I9: 130 | J9: 24 | K9: =SUM(J9*I9)
A10: Semeadura milheto | B10: 0.84 | C10: 500 | D10: =C10*B10 | G10: Oleo cambio | H10: lts | I10: 70 | J10: 10 | K10: =SUM(J10*I10)
A11: Adubação a lanço KCl | B11: 0.75 | C11: 2350 | D11: =C11*B11 | G11: Oleo selenia 10w30 | H11: lts | I11: 40 | J11: 4 | K11: =SUM(J11*I11)
A12: Adubação a lanço SS | B12: 0.75 | C12: 1600 | D12: =C12*B12 | G12: Oleo plus 50 4 | H12: lts | I12: 35 | J12: 80 | K12: =SUM(J12*I12)
A13: Adubação plantio | B13: 4 | C13: 915 | D13: =C13*B13 | G13: Oleo 15w40 | H13: lts | I13: 25 | J13: 400 | K13: =SUM(J13*I13)
A14: Ureia | B14: 1.3 | C14: 2300 | D14: =C14*B14 | G14: OLEO 424 | H14: lts | I14: 30 | J14: 350 | K14: =SUM(J14*I14)
A15: Aplicação quimicos | B15: 0.7 | C15: 15000 | D15: =C15*B15 | G15: OLEO 68 | H15: lts | I15: 20 | J15: 60 | K15: =SUM(J15*I15)
A16: Manutençao de estrradas | C16: 677.9661 | D16: 4000
A17: F4000 melosa | C17: 508.47458 | D17: 3000
A18: S10 Schu | C18: 406.77966 | D18: 2400
A19: F4000 aplicaçao | C19: 508.47458 | D19: 3000
A20: S10 Romerio | C20: 932.20339 | D20: 5500 | G20: dulub ATF | H20: lts | I20: 24 | J20: 12 | K20: =SUM(J20*I20)
A21: Pa carregadeira | C21: 677.9661 | D21: 4000 | G21: oleo lub. Ciser 300ml/200GRS | H21: PC | I21: 12.2 | J21: 4 | K21: =SUM(J21*I21)
A22: JD5403 | C22: 169.49153 | D22: 1000 | G22: Oleo SAE 10 | H22: lts | I22: 32 | J22: 4 | K22: =SUM(J22*I22)
A23: Ford cargo | C23: 508.47458 | D23: 3000 | G23: Oleo Dot 4 | H23: lts | I23: 32 | J23: 8 | K23: =SUM(J23*I23) | L23: =SUM(K4:K23)
A24: Ts | C24: 16.949153 | D24: 100
A25: Compras | C25: 254.23729 | D25: 1500
D26: =SUM(D2:D25)
D27: =D26*5.9

Sheet peças 
A1: Máquinas N | B1: Numero | C1: Outubro | D1: Novembro | E1: Dezembro | F1: Janeiro | G1: Fevereiro | H1: Março | I1: Abril | J1: Maio | K1: Junho | L1: Julho | M1: Agosto | N1: Setembro | O1: Total P/ Maquina 20/21
A2: Pa | B2: 95 | C2: 2500 | H2: 2500 | K2: 1300 | L2: 500 | O2: =SUM(C2:N2)
A3: M4030 | B3: 87 | C3: 40000 | D3: 5000 | E3: 5300 | F3: 6200 | G3: 5200 | H3: 4000 | I3: 2500 | J3: 4200 | K3: 10000 | L3: 6500 | M3: 3500 | N3: 15000 | O3: =SUM(C3:N3)
A4: DN4040 | C4: 3000 | D4: 2500 | E4: 600 | F4: 300 | G4: 2400 | H4: 500 | I4: 300 | K4: 6000 | N4: 12000 | O4: =SUM(C4:N4)
A5: Plant Braquiaria | C5: 1200 | D5: 1200 | M5: 2500 | O5: =SUM(C5:N5)
A6: Plant 2134 | B6: 10 | D6: 1700 | J6: 12000 | K6: 600 | L6: 600 | N6: 2000 | O6: =SUM(C6:N6)
A7: DB | B7: 55 | C7: 5100 | D7: 3000 | E7: 6300 | F7: 2500 | G7: 3100 | M7: 8000 | O7: =SUM(C7:N7)
A8: 8370R | B8: 32 | C8: 12000 | D8: 6000 | E8: 2400 | F8: 1200 | G8: 30000 | H8: 15000 | I8: 1875 | J8: 3000 | K8: 12000 | O8: =SUM(C8:N8)
A9: 8335R | B9: 41 | C9: 8000 | D9: 6000 | E9: 3100 | F9: 10000 | H9: 19000 | K9: 30000 | O9: =SUM(C9:N9)
A10: 5403 | B10: 35 | C10: 2500 | D10: 3200 | E10: 450 | H10: 600 | I10: 600 | J10: 450 | N10: 3500 | O10: =SUM(C10:N10)
A11: Bross preta | B11: 24 | C11: 800 | D11: 200 | E11: 200 | I11: 200 | M11: 600 | O11: =SUM(C11:N11)
A12: Bros | B12: 97 | C12: 800 | D12: 350 | I12: 350 | N12: 800 | O12: =SUM(C12:N12)
A13: Tilleer GTS | B13: 107 | I13: 2000 | O13: =SUM(C13:N13)
A14: Terrus Gts 12 H | B14: 109 | C14: 8000 | H14: 3500 | O14: =SUM(C14:N14)
A15: Rolo faca | D15: 2000 | O15: =SUM(C15:N15)
A16: Extratora | B16: 105 | O16: =SUM(C16:N16)
A17: F4000 | B17: 74 | C17: 5300 | D17: 1200 | E17: 1200 | F17: 600 | G17: 910 | H17: 4600 | O17: =SUM(C17:N17)
A18: Ford Cargo | C18: 20000 | D18: 2000 | E18: 1000 | F18: 1000 | G18: 2500 | H18: 2400 | J18: 10000 | N18: 2200 | O18: =SUM(C18:N18)
A19: Romerio s10 | B19: 53 | C19: 3000 | D19: 650 | E19: 2500 | F19: 3000 | H19: 750 | J19: 2700 | K19: 750 | L19: 10000 | M19: 1300 | N19: 2500 | O19: =SUM(C19:N19)
A20: S10 compras e schu | G20: ='Compras '!E23/3 | I20: 5000 | O20: =SUM(C20:N20)
A21: Pipa da agua | C21: 3300 | D21: 2500 | E21: 370 | G21: 660 | I21: 1800 | O21: =SUM(C21:N21)
A22: Oficina | C22: 5300 | D22: 5300 | E22: 5300 | F22: 5300 | G22: 5300 | H22: 5300 | I22: 5300 | J22: 5300 | K22: 5300 | L22: 5300 | M22: 5300 | N22: 5300 | O22: =SUM(C22:N22)
A23: Sede | C23: 4000 | D23: 4000 | E23: 4000 | F23: 4000 | G23: 4000 | H23: 4000 | I23: 4000 | J23: 4000 | K23: 4000 | L23: 4000 | M23: 4000 | N23: 4000 | O23: =SUM(C23:N23)
A24: F-4000 nova | C24: 2300 | D24: 1500 | F24: 1000 | H24: 2400 | J24: 500 | L24: 800 | N24: 1500 | O24: =SUM(C24:N24)
A25: Silo | C25: 10000 | F25: 6400 | G25: 6400 | I25: 6000 | J25: 6000 | O25: =SUM(C25:N25)
A26: Gerador | G26: 1200 | L26: 1300 | M26: 1200 | O26: =SUM(C26:N26)
A27: Escritorio | C27: 150 | D27: 600 | E27: 300 | F27: 700 | G27: 700 | H27: 700 | I27: 700 | J27: 200 | K27: 130 | L27: 1500 | M27: 1400 | N27: 2500 | O27: =SUM(C27:N27)
C28: =SUM(C2:C27) | D28: =SUM(D2:D27) | E28: =SUM(E2:E27) | F28: =SUM(F2:F27) | G28: =SUM(G2:G27) | H28: =SUM(H2:H27) | I28: =SUM(I2:I27) | J28: =SUM(J2:J27) | ... O28: =SUM(O2:O27)

Sheet Alimentação 
A1: Cantina | C1: Preços medio | D1: Quan.Itens | E1: Outubro | G1: Novembro | I1: Dezembro | K1: Janeiro | M1: Fevereiro | O1: Março | Q1: Abril | S1: Maio | U1: Junho | W1: Julho | Y1: Agosto | AA1: Setembro
A2: GAS | B2: UNIDAD | C2: 160.65 | D2: 8 | E2: =C2*D2 | F2: 5 | G2: =F2*C2 | H2: 7 | I2: =H2*C2 | J2: 7 | K2: =J2*C2 | L2: 6 | M2: =L2*C2 | N2: 6 | O2: =N2*C2 | P2: 7 | Q2: =P2*C2 | R2: 6 | S2: =R2*C2 | T2: 6 | U2: =T2*C2 | V2: 5 | W2: =V2*C2 | X2: 8 | Y2: =X2*C2 | Z2: 8 | AA2: =Z2*C2
A3: AÇUCAR 5 kg | B3: UNIDADE | C3: 25.2 | D3: 6 | E3: =C3*D3 | F3: 5 | G3: =F3*C3 | H3: 12 | I3: =H3*C3 | J3: 4 | K3: =J3*C3 | L3: 5 | M3: =L3*C3 | N3: 5 | O3: =N3*C3 | P3: 5 | Q3: =P3*C3 | R3: 5 | S3: =R3*C3 | T3: 5 | U3: =T3*C3 | V3: 4 | W3: =V3*C3 | X3: 4 | Y3: =X3*C3 | Z3: 4 | AA3: =Z3*C3
A4: AGUA SANITARIA CANDEIAS 1L | B4: UND | C4: 2.478 | D4: 15 | E4: =C4*D4 | F4: 8 | G4: =F4*C4 | H4: 10 | I4: =H4*C4 | J4: 18 | K4: =J4*C4 | L4: 8 | M4: =L4*C4 | N4: 9 | O4: =N4*C4 | P4: 9 | Q4: =P4*C4 | R4: 8 | S4: =R4*C4 | T4: 8 | U4: =T4*C4 | V4: 18 | W4: =V4*C4 | X4: 18 | Y4: =X4*C4 | Z4: 12 | AA4: =Z4*C4
A5: ARROZ BRANCO 5KG | B5: UNIDADE | C5: 26.5335 | D5: 12 | E5: =C5*D5 | F5: 15 | G5: =F5*C5 | H5: 10 | I5: =H5*C5 | J5: 9 | K5: =J5*C5 | L5: 15 | M5: =L5*C5 | N5: 12 | O5: =N5*C5 | P5: 12 | Q5: =P5*C5 | R5: 15 | S5: =R5*C5 | T5: 15 | U5: =T5*C5 | V5: 9 | W5: =V5*C5 | X5: 9 | Y5: =X5*C5 | Z5: 10 | AA5: =Z5*C5
A6: AZEITE OLIVA ANDORINHA EXT VIRG | B6: UND | C6: 56.68782 | D6: 3 | E6: =C6*D6 | F6: 5 | G6: =F6*C6 | H6: 2 | I6: =H6*C6 | J6: 6 | K6: =J6*C6 | L6: 5 | M6: =L6*C6 | N6: 7 | O6: =N6*C6 | P6: 7 | Q6: =P6*C6 | R6: 5 | S6: =R6*C6 | T6: 5 | U6: =T6*C6 | V6: 6 | W6: =V6*C6 | X6: 6 | Y6: =X6*C6 | Z6: 3 | AA6: =Z6*C6
A7: BACON PERDIGÃO | B7: KG | C7: 30.3765 | D7: 3 | E7: =C7*D7 | F7: 6 | G7: =F7*C7 | H7: 3 | I7: =H7*C7 | J7: 5 | K7: =J7*C7 | L7: 6 | M7: =L7*C7 | N7: 8 | O7: =N7*C7 | P7: 8 | Q7: =P7*C7 | R7: 6 | S7: =R7*C7 | T7: 6 | U7: =T7*C7 | V7: 5 | W7: =V7*C7 | X7: 5 | Y7: =X7*C7 | Z7: 3 | AA7: =Z7*C7
A8: BOBINA PLAST. 35X50CM | B8: UND | C8: 36.3825 | D8: 2 | E8: =C8*D8 | F8: 6 | G8: =F8*C8 | H8: 2 | I8: =H8*C8 | J8: 5 | K8: =J8*C8 | L8: 6 | M8: =L8*C8 | N8: 8 | O8: =N8*C8 | P8: 8 | Q8: =P8*C8 | R8: 6 | S8: =R8*C8 | T8: 6 | U8: =T8*C8 | V8: 5 | W8: =V8*C8 | X8: 5 | Y8: =X8*C8 | Z8: 3 | AA8: =Z8*C8
A9: BOV 2S OSSO | B9: KG | C9: 26.9115 | D9: 20 | E9: =C9*D9 | F9: 10 | G9: =F9*C9 | H9: 10 | I9: =H9*C9 | J9: 11 | K9: =J9*C9 | L9: 10 | M9: =L9*C9 | N9: 17 | O9: =N9*C9 | P9: 17 | Q9: =P9*C9 | R9: 10 | S9: =R9*C9 | T9: 10 | U9: =T9*C9 | V9: 11 | W9: =V9*C9 | X9: 11 | Y9: =X9*C9 | Z9: 6 | AA9: =Z9*C9
A10: BOV CARNE MOIDA | B10: KG | C10: 29.064 | D10: 10 | E10: =C10*D10 | F10: 13 | G10: =F10*C10 | H10: 11 | I10: =H10*C10 | J10: 21 | K10: =J10*C10 | L10: 13 | M10: =L10*C10 | N10: 26 | O10: =N10*C10 | P10: 26 | Q10: =P10*C10 | R10: 13 | S10: =R10*C10 | T10: 13 | U10: =T10*C10 | V10: 21 | W10: =V10*C10 | X10: 21 | Y10: =X10*C10 | Z10: 11 | AA10: =Z10*C10
A11: BOV CHA FORA BIFE | B11: KG | C11: 35.826 | D11: 11 | E11: =C11*D11 | F11: 18 | G11: =F11*C11 | H11: 11 | I11: =H11*C11 | J11: 20 | K11: =J11*C11 | L11: 18 | M11: =L11*C11 | N11: 32 | O11: =N11*C11 | P11: 32 | Q11: =P11*C11 | R11: 18 | S11: =R11*C11 | T11: 18 | U11: =T11*C11 | V11: 20 | W11: =V11*C11 | X11: 20 | Y11: =X11*C11 | Z11: 11 | AA11: =Z11*C11
A12: BOV FILÉ AGULHA | B12: KG | C12: 27.993 | D12: 11 | E12: =C12*D12 | F12: 17 | G12: =F12*C12 | H12: 11 | I12: =H12*C12 | J12: 20 | K12: =J12*C12 | L12: 17 | M12: =L12*C12 | N12: 32 | O12: =N12*C12 | P12: 32 | Q12: =P12*C12 | R12: 17 | S12: =R12*C12 | T12: 17 | U12: =T12*C12 | V12: 20 | W12: =V12*C12 | X12: 20 | Y12: =X12*C12 | Z12: 11 | AA12: =Z12*C12
A13: BOV MIOLO PALETA BIFE | B13: KG | C13: 35.5215 | D13: 5 | E13: =C13*D13 | F13: 16 | G13: =F13*C13 | H13: 11 | I13: =H13*C13 | J13: 20 | K13: =J13*C13 | L13: 16 | M13: =L13*C13 | N13: 32 | O13: =N13*C13 | P13: 32 | Q13: =P13*C13 | R13: 16 | S13: =R13*C13 | T13: 16 | U13: =T13*C13 | V13: 20 | W13: =V13*C13 | X13: 20 | Y13: =X13*C13 | Z13: 11 | AA13: =Z13*C13
... A24: FARINHA DE TRIGO SANADUVA | B24: UND | C24: 6.111 | D24: 6 | E24: =C24*D24 | F24: 12 | G24: =F24*C24 | H24: 6 | I24: =H24*C24 | J24: 6 | K24: =J24*C24 | L24: 12 | M24: =L24*C24 | N24: 17 | O24: =N24*C24 | P24: 17 | Q24: =P24*C24 | R24: 12 | S24: =R24*C24 | T24: 12 | U24: =T24*C24 | V24: 6 | W24: =V24*C24 | X24: 6 | Y24: =X24*C24 | Z24: 6 | AA24: =Z24*C24
A25: FLOCÃO BONOMILHO 500 G | B25: UND | C25: 1.9215 | D25: 25 | E25: =C25*D25 | F25: 16 | G25: =F25*C25 | H25: 12 | I25: =H25*C25 | K25: =J25*C25 | L25: 16 | M25: =L25*C25 | N25: 10 | O25: =N25*C25 | P25: 10 | R25: 16 | T25: 16
A26: FEIJAO CAR PADIM TP-1 1kg | B26: UND | C26: 7.35 | D26: 31 | E26: =C26*D26 | F26: 42 | G26: =F26*C26 | H26: 31 | I26: =H26*C26 | J26: 42 | K26: =J26*C26 | L26: 42 | M26: =L26*C26 | N26: 60 | O26: =N26*C26 | P26: 60 | Q26: =P26*C26 | R26: 42 | S26: =R26*C26 | T26: 42 | U26: =T26*C26 | V26: 42 | W26: =V26*C26 | X26: 42 | Y26: =X26*C26 | Z26: 30 | AA26: =Z26*C26
A27: FERM. FERMIPAM 500G | B27: UND | C27: 21.63 | D27: 3 | E27: =C27*D27 | F27: 4 | G27: =F27*C27 | H27: 2 | I27: =H27*C27 | J27: 4 | K27: =J27*C27 | L27: 4 | M27: =L27*C27 | N27: 3 | O27: =N27*C27 | P27: 3 | Q27: =P27*C27 | R27: 4 | S27: =R27*C27 | T27: 4 | U27: =T27*C27 | V27: 4 | W27: =V27*C27 | X27: 4 | Y27: =X27*C27 | Z27: 2 | AA27: =Z27*C27
A28: FRIATO COXA SOBRE COXA | B28: KG | C28: 10.6365 | D28: 41 | E28: =C28*D28 | F28: 50 | G28: =F28*C28 | H28: 41 | I28: =H28*C28 | J28: 45 | K28: =J28*C28 | L28: 50 | M28: =L28*C28 | N28: 60 | O28: =N28*C28 | P28: 60 | Q28: =P28*C28 | R28: 50 | S28: =R28*C28 | T28: 50 | U28: =T28*C28 | V28: 45 | W28: =V28*C28 | X28: 45 | Y28: =X28*C28 | Z28: 39 | AA28: =Z28*C28
A29: FRUTA ABACAXI | B29: UND | C29: 9.786 | D29: 4 | E29: =C29*D29 | F29: 7 | G29: =F29*C29 | H29: 3 | I29: =H29*C29 | J29: 2 | K29: =J29*C29 | L29: 7 | M29: =L29*C29 | N29: 6 | O29: =N29*C29 | P29: 6 | Q29: =P29*C29 | R29: 7 | S29: =R29*C29 | T29: 7 | U29: =T29*C29 | V29: 2 | W29: =V29*C29 | X29: 2 | Y29: =X29*C29 | Z29: 3 | AA29: =Z29*C29
A30: FRUTA BANANA NANICA | B30: KG | C30: 3.3075 | D30: 20 | E30: =C30*D30 | F30: 35 | G30: =F30*C30 | H30: 21 | I30: =H30*C30 | J30: 20 | K30: =J30*C30 | L30: 35 | M30: =L30*C30 | N30: 35 | O30: =N30*C30 | P30: 35 | Q30: =P30*C30 | R30: 35 | S30: =R30*C30 | T30: 35 | U30: =T30*C30 | V30: 20 | W30: =V30*C30 | X30: 20 | Y30: =X30*C30 | Z30: 20 | AA30: =Z30*C30
A31: FRUTA LARANJA | B31: KG | C31: 3.7275 | D31: 21 | E31: =C31*D31 | F31: 35 | G31: =F31*C31 | H31: 21 | I31: =H31*C31 | J31: 21 | K31: =J31*C31 | L31: 35 | M31: =L31*C31 | N31: 25 | O31: =N31*C31 | P31: 25 | Q31: =P31*C31 | R31: 35 | S31: =R31*C31 | T31: 35 | U31: =T31*C31 | V31: 21 | W31: =V31*C31 | X31: 21 | Y31: =X31*C31 | Z31: 20 | AA31: =Z31*C31
A32: FRUTA MACA FUJI | B32: KG | C32: 11.7075 | D32: 17 | E32: =C32*D32 | F32: 25 | G32: =F32*C32 | H32: 17 | I32: =H32*C32 | J32: 25 | K32: =J32*C32 | L32: 25 | M32: =L32*C32 | N32: 25 | O32: =N32*C32 | P32: 25 | Q32: =P32*C32 | R32: 25 | S32: =R32*C32 | T32: 25 | U32: =T32*C32 | V32: 25 | W32: =V32*C32 | X32: 25 | Y32: =X32*C32 | Z32: 16 | AA32: =Z32*C32
A33: FRUTA MAMAO | B33: KG | C33: 2.709 | D33: 3 | E33: =C33*D33 | F33: 5 | G33: =F33*C33 | H33: 3 | I33: =H33*C33 | J33: 5 | K33: =J33*C33 | L33: 5 | M33: =L33*C33 | N33: 2 | O33: =N33*C33 | P33: 2 | Q33: =P33*C33 | R33: 5 | S33: =R33*C33 | T33: 5 | U33: =T33*C33 | V33: 5 | W33: =V33*C33 | X33: 5 | Y33: =X33*C33 | Z33: 3 | AA33: =Z33*C33
A34: FRUTA MELANCIA | B34: KG | C34: 2.709 | D34: 24 | E34: =C34*D34 | F34: 35 | G34: =F34*C34 | H34: 20 | I34: =H34*C34 | J34: 35 | K34: =J34*C34 | L34: 35 | M34: =L34*C34 | N34: 35 | O34: =N34*C34 | P34: 35 | Q34: =P34*C34 | R34: 35 | S34: =R34*C34 | T34: 35 | U34: =T34*C34 | V34: 35 | W34: =V34*C34 | X34: 35 | Y34: =X34*C34 | Z34: 22 | AA34: =Z34*C34
A35: ISQUEIRO BIC MAXI 1X1 | B35: UND | C35: 5.5125 | D35: 7 | E35: =C35*D35 | F35: 0 | G35: =F35*C35 | H35: 0 | I35: =H35*C35 | J35: 0 | K35: =J35*C35 | L35: 0 | M35: =L35*C35 | N35: 0 | O35: =N35*C35 | P35: 0 | Q35: =P35*C35 | R35: 0 | S35: =R35*C35 | T35: 0 | U35: =T35*C35 | V35: 0 | W35: =V35*C35 | X35: 0 | Y35: =X35*C35 | AA35: =Z35*C35
A36: LAVA LOUCAS MINUANO | B36: UND | C36: 2.2155 | D36: 24 | E36: =C36*D36 | F36: 35 | G36: =F36*C36 | H36: 19 | I36: =H36*C36 | J36: 21 | K36: =J36*C36 | L36: 35 | M36: =L36*C36 | N36: 35 | O36: =N36*C36 | P36: 35 | Q36: =P36*C36 | R36: 35 | S36: =R36*C36 | T36: 35 | U36: =T36*C36 | V36: 21 | W36: =V36*C36 | X36: 21 | Y36: =X36*C36 | Z36: 24 | AA36: =Z36*C36
A37: LIMP PESADA CANDEIAS GEL LAV 1 L | B37: UND | C37: 8.925 | D37: 12 | E37: =C37*D37 | F37: 25 | G37: =F37*C37 | H37: 10 | I37: =H37*C37 | J37: 10 | K37: =J37*C37 | L37: 25 | M37: =L37*C37 | N37: 10 | O37: =N37*C37 | P37: 10 | Q37: =P37*C37 | R37: 25 | S37: =R37*C37 | T37: 25 | U37: =T37*C37 | V37: 10 | W37: =V37*C37 | X37: 10 | Y37: =X37*C37 | Z37: 24 | AA37: =Z37*C37
A38: LIMPA ALUMINIO POLITRIZ LIMAO 500 ML | B38: UND | C38: 3.1395 | D38: 12 | E38: =C38*D38 | F38: 16 | G38: =F38*C38 | H38: 10 | I38: =H38*C38 | J38: 22 | K38: =J38*C38 | L38: 16 | M38: =L38*C38 | N38: 22 | O38: =N38*C38 | P38: 22 | Q38: =P38*C38 | R38: 16 | S38: =R38*C38 | T38: 16 | U38: =T38*C38 | V38: 22 | W38: =V38*C38 | X38: 22 | Y38: =X38*C38 | Z38: 24 | AA38: =Z38*C38
A39: LIMPA CANDEIAS CERAMICA 1 L | B39: UND | C39: 7.791 | D39: 12 | E39: =C39*D39 | F39: 30 | G39: =F39*C39 | H39: 10 | I39: =H39*C39 | J39: 6 | K39: =J39*C39 | L39: 30 | M39: =L39*C39 | N39: 16 | O39: =N39*C39 | P39: 16 | Q39: =P39*C39 | R39: 30 | S39: =R39*C39 | T39: 30 | U39: =T39*C39 | V39: 6 | W39: =V39*C39 | X39: 6 | Y39: =X39*C39 | Z39: 24 | AA39: =Z39*C39
A40: LIMPA VEJA MULTIUSO ORIG LV500 | B40: UND | C40: 5.985 | D40: 24 | E40: =C40*D40 | F40: 25 | G40: =F40*C40 | H40: 20 | I40: =H40*C40 | J40: 8 | K40: =J40*C40 | L40: 25 | M40: =L40*C40 | N40: 16 | O40: =N40*C40 | P40: 16 | Q40: =P40*C40 | R40: 25 | S40: =R40*C40 | T40: 25 | U40: =T40*C40 | V40: 8 | W40: =V40*C40 | X40: 8 | Y40: =X40*C40 | Z40: 24 | AA40: =Z40*C40
A41: LING. MISTA FRICO | B41: KG | C41: 21.21 | D41: 6 | E41: =C41*D41 | F41: 12 | G41: =F41*C41 | H41: 10 | I41: =H41*C41 | J41: 10 | K41: =J41*C41 | L41: 12 | M41: =L41*C41 | N41: 12 | O41: =N41*C41 | P41: 12 | Q41: =P41*C41 | R41: 12 | S41: =R41*C41 | T41: 12 | U41: =T41*C41 | V41: 10 | W41: =V41*C41 | X41: 10 | Y41: =X41*C41 | Z41: 6 | AA41: =Z41*C41
A42: LING. FRICO CALABRESA DEF | B42: KG | C42: 26.92746 | D42: 4 | E42: =C42*D42 | F42: 7 | G42: =F42*C42 | H42: 3 | I42: =H42*C42 | J42: 5 | K42: =J42*C42 | L42: 7 | M42: =L42*C42 | N42: 6 | O42: =N42*C42 | P42: 6 | Q42: =P42*C42 | R42: 7 | S42: =R42*C42 | T42: 7 | U42: =T42*C42 | V42: 5 | W42: =V42*C42 | X42: 5 | Y42: =X42*C42 | Z42: 3 | AA42: =Z42*C42
A43: LING. NOBRE MISTA | B43: KG | C43: 22.407 | D43: 10 | E43: =C43*D43 | F43: 7 | G43: =F43*C43 | H43: 8 | I43: =H43*C43 | J43: 4 | K43: =J43*C43 | L43: 7 | M43: =L43*C43 | N43: 5 | O43: =N43*C43 | P43: 5 | Q43: =P43*C43 | R43: 7 | S43: =R43*C43 | T43: 7 | U43: =T43*C43 | V43: 4 | W43: =V43*C43 | X43: 4 | Y43: =X43*C43 | Z43: 3 | AA43: =Z43*C43
A44: LINGUI AURORA FGO | B44: KG | C44: 22.47 | D44: 9 | E44: =C44*D44 | F44: 18 | G44: =F44*C44 | H44: 8 | I44: =H44*C44 | J44: 2 | K44: =J44*C44 | L44: 18 | M44: =L44*C44 | N44: 16 | O44: =N44*C44 | P44: 16 | Q44: =P44*C44 | R44: 18 | S44: =R44*C44 | T44: 18 | U44: =T44*C44 | V44: 2 | W44: =V44*C44 | X44: 2 | Y44: =X44*C44 | Z44: 8 | AA44: =Z44*C44
A45: LUVA NOBRE PLAST DESC 100x1 | B45: UND | C45: 19.005 | D45: 2 | E45: =C45*D45 | F45: 2 | G45: =F45*C45 | H45: 2 | I45: =H45*C45 | J45: 2 | K45: =J45*C45 | L45: 2 | M45: =L45*C45 | N45: 2 | O45: =N45*C45 | P45: 2 | Q45: =P45*C45 | R45: 2 | S45: =R45*C45 | T45: 2 | U45: =T45*C45 | V45: 2 | W45: =V45*C45 | X45: 2 | Y45: =X45*C45 | Z45: 1 | AA45: =Z45*C45
A46: MAC PAULISTA SEM ESPAGUETE 500G | B46: UND | C46: 3.003 | D46: 20 | E46: =C46*D46 | F46: 15 | G46: =F46*C46 | H46: 14 | I46: =H46*C46 | J46: 20 | K46: =J46*C46 | L46: 15 | M46: =L46*C46 | N46: 16 | O46: =N46*C46 | P46: 16 | Q46: =P46*C46 | R46: 15 | S46: =R46*C46 | T46: 15 | U46: =T46*C46 | V46: 20 | W46: =V46*C46 | X46: 20 | Y46: =X46*C46 | Z46: 11 | AA46: =Z46*C46
A47: MASSA LASANHA DONA BENTA | B47: UND | C47: 7.623 | D47: 4 | E47: =C47*D47 | F47: 6 | G47: =F47*C47 | H47: 4 | I47: =H47*C47 | J47: 5 | K47: =J47*C47 | L47: 6 | M47: =L47*C47 | N47: 5 | O47: =N47*C47 | P47: 5 | Q47: =P47*C47 | R47: 6 | S47: =R47*C47 | T47: 6 | U47: =T47*C47 | V47: 5 | W47: =V47*C47 | X47: 5 | Y47: =X47*C47 | Z47: 4 | AA47: =Z47*C47
... A62: SALSICHA FRIATO CONG. | B62: KG | C62: 9.849 | D62: 10 | E62: =C62*D62 | F62: 12 | G62: =F62*C62 | H62: 6 | I62: =H62*C62 | J62: 10 | K62: =J62*C62 | L62: 12 | M62: =L62*C62 | N62: 10 | O62: =N62*C62 | P62: 10 | Q62: =P62*C62 | R62: 12 | S62: =R62*C62 | T62: 12 | U62: =T62*C62 | V62: 10 | W62: =V62*C62 | X62: 10 | Y62: =X62*C62 | Z62: 6 | AA62: =Z62*C62
A63: Suino granja | B63: Kg | C63: 15 | D63: 300 | E63: =C63*D63
C64: 0
...

Sheet Utilidades e Veiculos
A2: Radoll/Silo | B2: Consumo kw/h/mês fora Ponta | C2: Consumo kw/h/mês na Ponta | D2: Demanda | E2: R$ | G2: Radoll/Sede | H2: Consumo kw/h/mês -TUSD | I2: Consumo kw/h/mês TE | J2: Bandeira vermelha | K2: R$ | M2: INTERNET | N2: TOTAL | P2: Total
A3: Outubro | B3: 1623 | C3: 108 | D3: 33 | E3: =(B3*0.45)+(C3*3.9)+(D3*49.68)+200 | G3: Outubro | K3: 100 | M3: Outurbro | N3: 240 | P3: =SUM(N3,K3,E3)
A4: Novembro | B4: 2200 | C4: 47 | D4: 34 | E4: =(B4*0.45)+(C4*3.9)+(D4*49.68)+200 | G4: Novembro | K4: 100 | M4: Novembro | N4: 240 | P4: =SUM(N4,K4,E4)
A5: Dezembro | B5: 2400 | C5: 60 | D5: 34 | E5: =(B5*0.45)+(C5*3.9)+(D5*49.68)+200 | G5: Dezembro | K5: 100 | M5: Dez | N5: 240 | P5: =SUM(N5,K5,E5)
A6: Janeiro | B6: 1000 | C6: 127 | D6: 40 | E6: =(B6*0.45)+(C6*3.9)+(D6*49.68)+200 | G6: Janeiro | K6: 100 | M6: Jan | N6: 240 | P6: =SUM(N6,K6,E6)
A7: Fevereiro | B7: 1720 | C7: 72 | D7: 70 | E7: =(B7*0.45)+(C7*3.9)+(D7*49.68)+200 | G7: Fevereiro | K7: 100 | M7: Fevereiro | N7: 240 | P7: =SUM(N7,K7,E7)
A8: Março | B8: 1620 | C8: 84 | D8: 7 | E8: =(B8*0.45)+(C8*3.9)+(D8*49.68)+200 | G8: Março | K8: 100 | M8: Março | N8: 240 | P8: =SUM(N8,K8,E8)
A9: Abril | B9: 10700 | C9: 240 | D9: 140 | E9: =(B9*0.45)+(C9*3.9)+(D9*49.68)+200 | G9: Abril | K9: 100 | M9: Abril | N9: 240 | P9: =SUM(N9,K9,E9)
A10: Maio | B10: 3350 | C10: 57 | D10: 70 | E10: =(B10*0.45)+(C10*3.9)+(D10*49.68)+200 | G10: Maio | K10: 100 | M10: Maio | N10: 240 | P10: =SUM(N10,K10,E10)
A11: Junho | B11: 1471 | C11: 50 | D11: 42 | E11: =(B11*0.45)+(C11*3.9)+(D11*49.68)+200 | G11: Junho | K11: 100 | M11: Junho | N11: 240 | P11: =SUM(N11,K11,E11)
A12: Julho | B12: 1300 | C12: 55 | D12: 42 | E12: =(B12*0.45)+(C12*3.9)+(D12*49.68)+200 | G12: Julho | K12: 100 | M12: Julho | N12: 240 | P12: =SUM(N12,K12,E12)
A13: Agosto | B13: 1200 | C13: 30 | D13: 41 | E13: =(B13*0.45)+(C13*3.9)+(D13*49.68)+200 | G13: Agosto | K13: 100 | M13: Agosto | N13: 240 | P13: =SUM(N13,K13,E13)
A14: Setembro | B14: 1100 | C14: 42 | D14: 45 | E14: =(B14*0.45)+(C14*3.9)+(D14*49.68)+200 | G14: Setembro | K14: 100 | M14: Setembro | N14: 240 | P14: =SUM(N14,K14,E14)
B15: 118200 | C15: Cambio 5,20 | D15: =D14*5.2 | E15: =SUM(E3:E14) | I15: =I14*5.2 | K15: =SUM(K3:K14) | N15: =SUM(N3:N14) | P15: =SUM(P3:P14)
B18: Planilha de Veiculos Agroservice - Exercício 2022 | C18: Planilha de Veiculos Agroservice - Exercício 2022 | D18: Planilha de Veiculos Agroservice - Exercício 2022 | E18: Planilha de Veiculos Agroservice - Exercício 2022 | F18: Planilha de Veiculos Agroservice - Exercício 2022 | G18: Planilha de Veiculos Agroservice - Exercício 2022 | H18: Planilha de Veiculos Agroservice - Exercício 2022 | I18: Planilha de Veiculos Agroservice - Exercício 2022
B19: veiculos | C19: Chassi: | D19: Renavam: | E19: Placa: | F19: Valor normal | G19: Valor c desconto | H19: CRLV -2021 | I19: Situação | J19: Proprietarios
A20: F4000 2019 | B20: F4000 a | C20: 9BFLF47P6KB017257 | D20: 1183397566 | E20: PRV3B48 | G20: 1132 | I20: ok | J20: AGROINVEST
B21: F4000 | C21: 9BFLF4799BB098143 | D21: 464016150 | E21: NZU-7394 | G21: 622.85 | I21: ok | J21: AGROSERVICE
B22: F4000 a | C22: 9BFLF47949B061110 | D22: 124118003 | E22: JSA-0223 | G22: 544.25 | I22: ok | J22: JOHN DANIEL CARROLL
B23: F4000 | C23: 9BFLF4798AB077721 | D23: 273513079 | E23: NYK-7967 | G23: 581.45 | I23: ok | J23: JOHN DANIEL CARROLL
B24: F4000 | C24: 9BFLF4791AB076751 | D24: 273494791 | E24: NYK-4040 | G24: 581.45 | I24: ok | J24: JOHN DANIEL CARROLL
B25: F4000 | C25: 9BFLF4799BB098370 | D25: 471104248 | E25: NZY-3157 | G25: 622.85 | I25: ok | J25: AGROSERVICE
B26: F4000 | C26: 9BFLF4797BB087433 | D26: 337348677 | E26: NYZ-2185 | G26: 622.85 | I26: ok | J26: AGROSERVICE
B27: VOLKSWAGEN 23230 NOVO | C27: 9536G8243LR003331 | D27: 1197330574 | E27: PLT-5I44 | G27: 1939.19 | I27: ok | J27: AGROSERVICE
B28: FORD 2422 E | C28: 9BFYCEHVX7BB99495 | D28: 954271483 | E28: JRC-6349 | G28: 840.8 | I28: ok | J28: JOHN DANIEL CARROLL
B29: FORD 2422 E a | C29: 9BFYCEHV47BB89394 | D29: 954273478 | E29: JRE-1214 | G29: 840.8 | I29: ok | J29: JOHN DANIEL CARROLL
B30: ONIBUS | C30: 9BM384088NB944904 | D30: 319418359 | E30: KOD-1895 | G30: 149.16 | I30: ok | J30: JHON DANIEL CARROLL
B31: F350 | C31: 9BFJF37939B062346 | D31: 124117074 | E31: JSA-9307 | G31: 589.9 | I31: ok/v | J31: JOHN DANIEL CARROLL
B32: STRADA BRANCA NOVO 2018 | C32: 9BD5781FFHY167654 | D32: 1129961807 | E32: PKQ-1249 | G32: 1049.6 | I32: ok | J32: AGROSERVICE | K32: office | L32: ok
B33: EVOQUE PURE | C33: SALVA2BG4DH724928 | D33: 505863987 | E33: OUD-7408 | G33: 2114.6 | I33: ok | J33: AGROSERVICE | K33: office | L33: ok
B34: ONIX NOVO 2018 | C34: 9BGKS48V0JG146937 | D34: 1124430986 | E34: PKO-5490 | G34: 1189.01 | I34: ok | J34: AGROSERVICE | K34: office | L34: ok
B35: FOX | C35: 9BWKA05Z664065844 | D35: 865893497 | E35: JGO-6738 | G35: 149.16 | I35: ok | J35: JOHN DANIEL CARROLL | K35: office | L35: ok
B36: QUANTUM | C36: 9BWZZZ33ZNP030722 | D36: 606002928 | E36: BLG-6647 | G36: 149.16 | I36: ok/v | J36: JOHN DANIEL CARROLL | K36: office | L36: ok
B37: S-10 Nova Prata - Schuh | C37: 9BG148FK0LC429210 | D37: 1226385033 | E37: QTZ3H12 | G37: 3822.27 | I37: ok | J37: AGROSERVICE
B38: S-10 - Dan | C38: 9BG148FK0FC409677 | D38: 1036472890 | E38: OZV-5618 | G38: 2624.66 | I38: ok | J38: AGROSERVICE | K38: office | L38: ok
B39: S-10 - nova Branca - Davi | C39: 9BG148DK0KC406908 | D39: 1154492491 | E39: QOK-8422 | G39: 2927.76 | I39: ok | J39: AGROSERVICE | K39: radoll
B40: S-10 - Dpt. Compras | C40: 9BG144DK0LC431427 | D40: 1218843494 | E40: QTW2B92 | G40: 3580.85 | I40: ok | J40: AGROSERVICE
B41: Moto bros 150 ano 2011 | C41: 9C2KD0580CR500290 | D41: 425829022 | E41: OGL-7521 | G41: 149.16 | I41: ok | J41: AGROSERVICE
B42: Moto xtz 125 ano 2011 | C42: 9C6KE1260C0026212 | D42: 459372858 | E42: OGZ-3372 | G42: 149.16 | I42: ok | J42: AGROSERVICE
B43: Moto bros 150 ano 2011 a | C43: 9C2KD0560CR500617 | D43: 394245792 | E43: OGW-7606 | G43: 149.16 | I43: ok | J43: AGROSERVICE
...

Sheet Supriment-Ser Profiss
A1: Suprimentos | B1: Suprimentos | C1: Suprimentos | F1: Serviços Profissionais | G1: Serviços Profissionais | H1: Serviços Profissionais | I1: Serviços Profissionais
A2: Produto | B2: Quantidade | C2: R$ Total | F2: Serviço | G2: Referncia (mensal, anual, p/serviço) | H2: R$ Total
A3: Confraternização Final de ano | B3: 1 | C3: =RH!C22 | F3: Focu Consultoria 5X 9000 | G3: 75000 | H3: 75000
A4: Agroinvest | B4: Agroinvest | C4: Agroinvest | F4: Davi, mapas de fertilidade e prescrição | G4: R$0,28/há de mapas
A5: Confraternização Trimestral | C5: =RH!C38 | F5: Oeste Acessoria R$750,20x12meses | G5: 12 | H5: =((1212*0.682)*15000)/5750 | I5: Rateado com Agroservice
A6: Baners Prioridades | C6: ='Supriment-Ser Profiss'!H1 | F6: Cooperfarms comissão de compra de quimicos | G6: U$$ * 1% | H6: =(211666*1%)*'Orçam-Realiza'!D29 | M6: 606.98
A7: Datas comemorativas | C7: =RH!C34 | F7: Armazenagem de Quimicos ( n° pallet) | G7: 527 Pallet | H7: =SUM(G11:O11)
C8: =SUM(C5:C7) | G8: Out | H8: 248.24 | I8: Dez | J8: Jan | K8: Fev | L8: Mar | M8: Abr | N8: Mai | O8: Jun
A9: Materiasis Eletricos | B9: 1 | C9: 5000 | F9: Lts Quimic | G9: =40500/2 | H9: =50580/2 | I9: =48600/2 | J9: =49500/2 | K9: =43200/2 | L9: =34650/2 | M9: =27000/2 | N9: =24700/2 | O9: =25000/2
A10: Grafica, Papelaria, Higiene e Limpeza. | F10: N° Pallet | G10: 20 | H10: 20 | I10: 20 | J10: 2 | K10: 2 | L10: 2 | M10: 2 | N10: 2 | O10: 2
A11: Calculadora | B11: 1 | C11: =Angelo!D4 | F11: R$/Pallet | G11: =G10*80+810 | H11: =H10*80+810 | I11: =I10*80+810 | J11: =J10*80+720 | K11: =K10*80+720 | L11: =L10*80+720 | M11: =M10*80+720 | N11: =N10*80+720 | O11: =O10*80+720
A12: Comodato impressora 12xR$ 240 | B12: 12 | C12: =Angelo!D5 | F12: Lavanderia (reaproveitamento de Uniformes)
A13: Concerto noobrak | B13: 1 | C13: =Angelo!D6 | F13: Manutençao dos AC | G13: 4 | H13: 3000
A14: Concerto ar condicionado | B14: 1 | C14: =Angelo!D7 | F14: Manutenção dos Radios de comunicação | G14: 1 | H14: 1000
A15: Caneta cx | B15: 1 | C15: =Angelo!D8 | F15: FFGU (Coleta, transporte, tratamento e disposição final) | G15: Quant | H15: Total
A16: Cx com 5 mil Granpos 26/6 para grampeador | B16: 1 | C16: =Angelo!D9 | F16: Lampada | G16: 3 | H16: =Angelo!D97
A17: Cx com 48 unidades de prendedor de papel 25mm | B17: 1 | C17: =Angelo!D10 | F17: Baterias | G17: 6 | H17: =Angelo!D98
A18: Cx com 12 unidades de prendedor de papel 51mm | B18: 2 | C18: =Angelo!D11 | F18: Residuos oleosos | G18: 20 | H18: =Angelo!D99
A19: Grampeador | B19: 1 | C19: =Angelo!D12 | F19: Residuos misto | G19: 60 | H19: =Angelo!D100
A20: Lampadas para escritorio | B20: 2 | C20: =Angelo!D13 | F20: Rejeitos | G20: 50 | H20: =Angelo!D101
A21: Lixeira 15 lt com pedal | B21: 0 | C21: =Angelo!D14 | F21: Plastico | G21: 50 | H21: =Angelo!D102 | J21: =I20*5.2
A22: Marcador permanente | B22: 6 | C22: =Angelo!D15 | F22: Borracha | G22: 70 | H22: =Angelo!D103 | I22: =SUM(I20:I21) | J22: =I21*5.2
A23: Marca texto verde | B23: 2 | C23: =Angelo!D16 | H23: =SUM(H16:H22) | J23: =SUM(J21:J22)
A24: Ticket lavoura soja e milho | C24: =Angelo!D19 | F24: Transporte Estagiarios (passagens onibus) | G24: 1 | H24: 600
A25: bico microaspersor | B25: 10 | C25: 101.25 | F25: Pesquisa ( Kasuya)
A26: caixa de descarga | B26: 1 | C26: 146 | F26: Kasuya (n° Tratamentos )
A27: condor escova | B27: 4 | C27: 33 | F27: ABAPA
A28: desinf 2l | B28: 5 | C28: 85 | F28: HVI (1,58/amostra fardo de 240 kg) | G28: 0 | H28: 0
A29: Detergente liq 500ml neutro | B29: 48 | F29: Anuidade (R$ 6/há) | G29: 0 | H29: 0
A30: detergente neutro 5l | B30: 6 | C30: 520 | H30: =SUM(H28:H29)
A31: Escova | B31: 4 | C31: 102 | F31: Treinamentos, Coaching, Reuniões Trimestrais | H31: =RH!C34
A32: esponja multiuso | B32: 10 | C32: 23 | F32: SF2 (Sinal GPS tratores) | G32: 2 | H32: 16000
A33: facão | B33: 1 | C33: 140 | F33: CREA
A34: familiar sup. Papel | B34: 9 | C34: 95 | F34: ART SAFRA (n° Matric.) | G34: 15 | H34: =G34*90
A35: fita veda rosca censi 18x10m | B35: 2 | C35: 24 | F35: ART José Victor | G35: 1 | H35: 600
A36: inseticida aerosol multi | B36: 1 | C36: 26 | F36: Anuidade Angelo | G36: 1 | H36: 40
A37: inseticidada aerosol citronela | B37: 1 | C37: 26 | F37: Anuidade Agroinvest | G37: 1 | H37: 3275.01
A38: lampada bulbo led 9w 6500k | B38: 15 | C38: 400 | H38: =SUM(H34:H37)
A39: Pá de bico c/cabo 120cm | B39: 1 | C39: 210 | F39: Vigilancia Fazenda (mensalidade) | G39: 12 | H39: =11930*G39
A40: Pá plastica | F40: Laboratorio de analises | G40: N° amostras
...

Sheet Folha pagamento 
B1: Salário | C1: Quiquenio | D1: Insalubridade | E1: Periculosidade | F1: HE 50% | G1: HE 100% | H1: DSR | I1: Adic. Férias | J1: 13º | K1: INSS Empre | L1: FGTS | M1: Total Mensal | N1: Total anual | T1: Out | U1: Nov | V1: Dez | W1: Jan | X1: Fev | Y1: Mar | Z1: Abr | AA1: Mai | AB1: Jun | AC1: Jul | AD1: Ago | AE1: Set
A2: Plantio e TS | S2: Romerio | AB2: férias
A3: Romerio | B3: 15000 | C3: =B3*10% | D3: 293 | E3: 0 | I3: =(B3+C3+D3)*33%/12 | J3: =SUM(A3:G3)/12 | K3: =SUM(B3:J3)*2.7% | L3: =SUM(B3:J3)*8% | M3: =SUM(B3:L3) | N3: =M3*12 | S3: Paulo Vitor | AB3: férias
A4: Paulo Vitor | B4: 3700 | D4: 293 | E4: 0 | F4: =(B4+D4)/220*1.5*24 | G4: =(B4+D4)/220*2*10 | H4: =(F4+G4)/26*4 | I4: =SUM(B4:H4)*33%/12 | J4: =SUM(A4:H4)*8% | K4: =SUM(B4:J4)*2.7% | L4: =SUM(F4:K4)*8% | M4: =SUM(B4:L4) | N4: =M4*12 | S4: Raimundo | AC4: férias
A5: Raimundo | B5: 2200 | E5: =B5*30% | F5: =(B5+E5)/220*1.5*20 | G5: =(B5+E5)/220*2*10 | H5: =(F5+G5)/26*4 | I5: =SUM(B5:H5)*33%/12 | J5: =SUM(A5:H5)*8% | K5: =SUM(B5:J5)*2.7% | L5: =SUM(F5:K5)*8% | M5: =SUM(B5:L5) | N5: =M5*12 | S5: Marcos Santana | AD5: férias
E6: =B6*30% | F6: =(B6+D6)/220*1.5*20 | G6: =(B6+D6)/220*2*15 | H6: =(F6+G6)/26*4 | I6: =SUM(B6:H6)*33%/12 | J6: =SUM(A6:H6)*8% | K6: =SUM(B6:J6)*2.7% | L6: =SUM(F6:K6)*8% | M6: =SUM(B6:L6) | N6: =M6*12 | S6: Wanderson | AC6: Férias
A7: Marcos Santana | B7: 4000 | D7: 293 | F7: =(B7+D7)/220*1.5*20 | G7: =(B7+D7)/220*2*10 | H7: =(F7+G7)/26*4 | I7: =SUM(B7:H7)*33%/12 | J7: =SUM(A7:H7)*8% | K7: =SUM(B7:J7)*2.7% | L7: =SUM(F7:K7)*8% | M7: =SUM(B7:L7) | N7: =M7*12 | S7: Wanderson | AC7: Férias
A8: Wanderson | B8: 6500 | D8: 293 | E8: 0 | I8: =(B8+C8+D8)*33%/12 | J8: =SUM(A8:G8)/12 | K8: =SUM(B8:J8)*2.7% | L8: =SUM(B8:J8)*8% | M8: =SUM(B8:L8) | N8: =M8*12 | S8: Bruno | AB8: Férias
A9: Bruno | B9: 3700 | D9: 293 | E9: 0 | F9: =(B9+D9)/220*1.5*20 | G9: =(B9+D9)/220*2*10 | H9: =(F9+G9)/26*4 | I9: =SUM(B9:H9)*33%/12 | J9: =SUM(A9:H9)*8% | K9: =SUM(B9:J9)*2.7% | L9: =SUM(F9:K9)*8% | M9: =SUM(B9:L9) | N9: =M9*12 | S9: Francidalva | AB9: Férias
A10: Motorista | B10: 3100 | D10: 293 | E10: 0 | F10: =(B10+D10)/220*1.5*20 | G10: =(B10+D10)/220*2*15 | H10: =(F10+G10)/26*4 | I10: =SUM(B10:H10)*33%/12 | J10: =SUM(A10:H10)*8% | K10: =SUM(B10:J10)*2.7% | L10: =SUM(F10:K10)*8% | M10: =SUM(B10:L10) | N10: =M10*6
A11: Nanci | B11: 2200 | F11: =(B11+D11)/220*1.5*5 | G11: =(B11+D11)/220*2*10 | H11: =(F11+G11)/26*4 | I11: =SUM(B11:H11)*33%/12 | J11: =SUM(A11:H11)*8% | K11: =SUM(B11:J11)*2.7% | L11: =SUM(F11:K11)*8% | M11: =SUM(B11:L11) | N11: =M11*12
A12: Francidalva | B12: 2500 | F12: =(B12+D12)/220*1.5*10 | G12: =(B12+D12)/220*2*7 | H12: =(F12+G12)/26*4 | I12: =SUM(B12:H12)*33%/12 | J12: =SUM(A12:H12)*8% | K12: =SUM(B12:J12)*2.7% | L12: =SUM(F12:K12)*8% | M12: =SUM(B12:L12) | N12: =M12*12 | S12: Fabio
A14: Wilton | B14: 2300 | D14: 293 | F14: =(B14+E14)/220*1.5*20 | G14: =(B14+E14)/220*2*10 | H14: =(F14+G14)/26*4 | I14: =SUM(B14:H14)*33%/12 | J14: =SUM(A14:H14)*8% | K14: =SUM(B14:J14)*2.7% | L14: =SUM(F14:K14)*8% | M14: =SUM(B14:L14) | N14: =M14*12
A15: Marcos magalhães | B15: 3300 | D15: 293 | E15: 0 | F15: =(B15+D15)/220*1.5*20 | G15: =(B15+D15)/220*2*8 | H15: =(F15+G15)/26*4 | I15: =SUM(B15:H15)*33%/12 | J15: =SUM(A15:H15)*8% | K15: =SUM(B15:J15)*2.7% | L15: =SUM(F15:K15)*8% | M15: =SUM(B15:L15) | N15: =M15*12
A16: Joelson | B16: 3500 | D16: 293 | E16: 0 | F16: =(B16+D16)/220*1.5*40 | G16: =(B16+D16)/220*2*15 | H16: =(F16+G16)/26*4 | I16: =SUM(B16:H16)*33%/12 | J16: =SUM(A16:H16)*8% | K16: =SUM(B16:J16)*2.7% | L16: =SUM(F16:K16)*8% | M16: =SUM(B16:L16) | N16: =M16*12
A17: Angelo | B17: 4254.95 | N17: =B17*12
A18: Rosivaldo | B18: =6300*0.3 | E18: 0 | I18: =(B18+C18+F17)*33%/12 | J18: =SUM(A18:G18)/12 | K18: =SUM(B18:J18)*2.7% | L18: =SUM(B18:J18)*8% | M18: =SUM(B18:L18) | N18: =M18*12
A19: Pedro | B19: 1321 | I19: =(B19+C19+G19)*33%/12 | J19: =SUM(A19:G19)/12 | K19: =SUM(B19:J19)*2.7% | L19: =SUM(B19:J19)*8% | M19: =SUM(B19:L19) | N19: =M19*12
A20: valdimir | B20: 2778.804 | E20: 0 | M20: =SUM(B20:L20) | N20: =M20*12
A21: Marcos schu | B21: 3000 | C21: =B21*5% | D21: 293 | E21: 0 | I21: =(B21+C21+F18)*33%/12 | J21: =SUM(A21:G21)/12 | K21: =SUM(B21:J21)*2.7% | L21: =SUM(B21:J21)*8% | M21: =SUM(B21:L21) | N21: =M21*3.6
A22: Estagiario | B22: 1500 | M22: =SUM(B22:L22)*2 | N22: =M22*12
A23: Cartâo vale transporte | B23: =RH!F1 | N23: =RH!I4
A24: Total | B24: =SUM(B3:B22) | D24: =SUM(D3:D22) | E24: =SUM(E3:E22) | F24: =SUM(F3:F22) | G24: =SUM(G3:G22) | H24: =SUM(H3:H22) | I24: =SUM(I3:I22) | J24: =SUM(J3:J22) | K24: =SUM(K3:K22) | ... M24: =SUM(M3:M22) | N24: =SUM(N3:N23)
N25: =N24-'Orçamento Resumo'!K8
N27: =N24/14
N28: =N27*2
N29: =N28/4
N40: =SUM(N27:N39)

Sheet Quimi. Fert. Semente
A3: Semente | B3: Semente | C3: Semente | D3: Semente | F3: Quimicos | G3: Quimicos | H3: Quimicos | I3: Quimicos | K3: Adubo | L3: Adubo | M3: Adubo | N3: Adubo
A4: Agroinvest | B4: Hectar | C4: U$/há | D4: Total | F4: Agroinvest | G4: Hectar | H4: U$/há | I4: Total | K4: Agroinvest | L4: Hectar | M4: U$/há | N4: Total
A5: Soja Intacta | B5: 900 | C5: 83.57 | D5: =B5*C5 | F5: Soja Intacta | G5: =B5 | H5: 154.15 | I5: =G5*H5 | K5: Soja | L5: =SUM(G5:G6) | M5: 105 | N5: =L5*M5
A6: Soja Convencional | B6: 0 | C6: 0 | D6: =B6*C6 | F6: Soja Convencional | G6: =B6 | H6: 0 | I6: =G6*H6 | K6: Milho | L6: =SUM(G7:G9) | M6: 406 | N6: =L6*M6
A7: Milho Refugio | B7: 0 | C7: 0 | D7: =B7*C7 | F7: Milho Refugio | G7: =B7 | H7: 0 | I7: =G7*H7 | K7: Algodão | L7: =SUM(G10:G13) | M7: 0 | N7: =L7*M7
A8: Milho Leptra | B8: 1380 | C8: 187 | D8: =B8*C8 | F8: Milho Leptra | G8: =B8 | H8: 138.61 | I8: =G8*H8
A9: Milho PRO/PW | B9: 0 | C9: 0 | D9: =B9*C9 | F9: Milho PRO/PW | G9: =B9 | H9: 0 | I9: =G9*H9 | N9: =SUM(N5:N7)
A10: Algodão WS | B10: 0 | C10: 0 | D10: =B10*C10 | F10: Algodão WS | G10: =B10 | H10: 0 | I10: =G10*H10 | N10: =N9*'Orçam-Realiza'!D29
A11: Algodão GLT | B11: 0 | C11: 0 | D11: =B11*C11 | F11: Algodão GLT | G11: =B11 | H11: 0 | I11: =G11*H11
A12: Algodão B2RRF | B12: 0 | C12: 0 | D12: =B12*C12 | F12: Algodão B2RRF | G12: =B12 | H12: 0 | I12: =G12*H12
A13: Algodão RR | B13: 0 | C13: 0 | D13: =B13*C13 | F13: Algodão RR | G13: =B13 | H13: 0 | I13: =G13*H13
D14: =SUM(D5:D13) | I14: =SUM(I5:I13)
D15: =D14*'Orçam-Realiza'!D29 | I15: =I14*'Orçam-Realiza'!D29
F21: SAFRA 25-26 | G21: SAFRA 25-26 | H21: SAFRA 25-26 | I21: SAFRA 25-26 | J21: SAFRA 25-26
F22: Soja | G22: =C5+H5+M5 | H22: 900 | I22: =H22*G22 | J22: =I22*'Orçam-Realiza'!$D$29
F23: Milho | G23: =C8+H8+M6 | H23: 1380 | I23: =H23*G23 | J23: =I23*'Orçam-Realiza'!$D$29
I24: =SUM(I22:I23) | J24: =I24*'Orçam-Realiza'!$D$29
F26: SAFRA 24-25 | G26: SAFRA 24-25 | H26: SAFRA 24-25 | I26: SAFRA 24-25 | J26: SAFRA 24-25
F27: Soja | G27: 358.68977 | H27: 1380 | I27: 494991.88 | J27: 2771954.5
F28: Milho | G28: 694.25046 | H28: 900 | I28: 624825.41 | J28: 3499022.3
I29: 1119817.3 | J29: 6270976.8
F31: SAFRA 23-24 | G31: SAFRA 23-24 | H31: SAFRA 23-24 | I31: SAFRA 23-24 | J31: SAFRA 23-24
F32: Soja | G32: 360.39 | H32: 1600 | I32: =H32*G32 | J32: =I32*'Orçam-Realiza'!$D$29
F33: Milho | G33: 823.43 | H33: 700 | I33: =H33*G33 | J33: =I33*'Orçam-Realiza'!$D$29
I34: =SUM(I32:I33) | J34: =I34*'Orçam-Realiza'!$D$29
F36: SAFRA 22-23 | G36: SAFRA 22-23 | H36: SAFRA 22-23 | I36: SAFRA 22-23 | J36: SAFRA 22-23
F37: Soja | G37: 360.69 | H37: 1600 | I37: =H37*G37 | J37: =I37*'Orçam-Realiza'!$D$29
F38: Milho | G38: =SUM(C8,H8,M6) | H38: 700 | I38: =H38*G38 | J38: =I38*'Orçam-Realiza'!$D$29
I39: =SUM(I37:I38) | J39: =I39*'Orçam-Realiza'!$D$29
F40: SAFRA 21-22 | G40: SAFRA 21-22 | H40: SAFRA 21-22 | I40: SAFRA 21-22 | J40: SAFRA 21-22
F41: Soja | G41: 347.57 | H41: 4127 | I41: =H41*G41 | J41: =I41*5.15
F42: Milho | G42: 667.19 | H42: 1642 | I42: =H42*G42 | J42: =I42*5.15
I43: =SUM(I41:I42) | J43: =SUM(J41:J42)
F44: SAFRA 20-21 | G44: SAFRA 20-21 | H44: SAFRA 20-21 | I44: SAFRA 20-21 | J44: SAFRA 20-21
F45: Soja | G45: =1221.02/5.4 | H45: 5750 | I45: =H45*G45 | J45: =I45*5.15
F46: Milho | G46: 0 | H46: =H9 | I46: =H46*G46 | J46: =I46*5.15
I47: =SUM(I45:I46) | J47: =SUM(J45:J46)

Sheet Contratação serviç.
A2: Operação | B2: Hectares | C2: SC/HÁ e R$/ha
A3: Colheita Soja e Milho | B3: 2300 | C3: 2.2 | D3: =(C3*2300)*120
A4: Safrinha | B4: 300 | C4: 1.8 | D4: =(C4*B4)*55
D5: =SUM(D3:D4)
A6: FRETE SOJA p TRADE | B6: FRETE SOJA p TRADE | C6: FRETE SOJA p TRADE | D6: FRETE SOJA p TRADE
B7: T produção | C7: T FOB | D7: Frete
A8: Agroinvest X BV | B8: 1290 | D8: =B8*15
A9: Agroinvest x Cargil | B9: 1020 | D9: =B9*50
A10: Agroinvest x Placas | B10: 1212 | D10: =B10*38
A11: FRETE p Secador e Silos | B11: FRETE p Secador e Silos | C11: FRETE p Secador e Silos | D11: FRETE p Secador e Silos
A12: Produto | B12: T | C12: R$/T | D12: Total Frete
D13: =C13*B13
A14: Soja | B14: 1200 | C14: 16 | D14: =C14*B14
A15: Milho | B15: 7000 | C15: 14 | D15: =C15*B15
D16: =C16*B16 | H16: Silo beg | I16: 4
C17: Cambio 5,20 | H17: Custo | I17: =(I16*2600)*1.1
C18: Total FRETE | D18: =SUM(D13:D17,D10) | F18: Silo bolsa | G18: =I17+I8
A19: TOTAL Seviçõs | B19: =D5+D8+D9+D10+D18
A23: Prancha para logistica de maquinas e equipamentos | B23: Prancha para logistica de maquinas e equipamentos | C23: Prancha para logistica de maquinas e equipamentos
A24: Equipamento | B24: KM
A25: Rolo faca | B25: 800 | C25: =B25*8.5
A26: Niveladora | B26: 800 | C26: =B26*8.5
A27: Fiat strada ou s10 | C27: =B27*15
A28: Trator alugado | C28: =B28*15
C29: =SUM(C25:C28)
A31: Fretes | B31: KM
A32: Quimicos | B32: 1260 | C32: =B32*4
A33: Embalagens | B33: 2 viagens | C33: 3000
A34: Cascalhos | B34: 4 viagens | C34: 5000
C35: =SUM(C32:C34)

Sheet Avião
A1: Orçamento 2025/2026 | B1: Orçamento 2025/2026 | C1: Orçamento 2025/2026 | D1: Orçamento 2025/2026 | E1: Orçamento 2025/2026 | F1: Orçamento 2025/2026 | G1: Orçamento 2025/2026 | H1: Orçamento 2025/2026 | I1: Orçamento 2025/2026 | J1: Orçamento 2025/2026 | K1: Orçamento 2025/2026 | L1: Orçamento 2025/2026 | M1: Orçamento 2025/2026 | N1: Orçamento 2025/2026 | O1: Orçamento 2025/2026 | P1: Orçamento 2025/2026 | Q1: Orçamento 2025/2026 | R1: Obs
A2: Orçamento 2025/2026 | B2: Orçamento 2025/2026 | C2: Orçamento 2025/2026 | D2: Orçamento 2025/2026 | E2: Orçamento 2025/2026 | F2: Orçamento 2025/2026 | G2: Orçamento 2025/2026 | H2: Orçamento 2025/2026 | I2: Orçamento 2025/2026 | J2: Orçamento 2025/2026 | K2: Orçamento 2025/2026 | L2: Orçamento 2025/2026 | M2: Orçamento 2025/2026 | N2: Orçamento 2025/2026 | O2: Orçamento 2025/2026 | P2: Orçamento 2025/2026 | Q2: Orçamento 2025/2026 | X2: ORÇAMENTO BASE ZERO ACFT SENECA V (PR-PME) /Meridian500 | Y2: ORÇAMENTO BASE ZERO ACFT SENECA V (PR-PME) /Meridian500 | Z2: ORÇAMENTO BASE ZERO ACFT SENECA V (PR-PME) /Meridian500 | AA2: ORÇAMENTO BASE ZERO ACFT SENECA V (PR-PME) /Meridian500 | AB2: ORÇAMENTO BASE ZERO ACFT SENECA V (PR-PME) /Meridian500 | AC2: ORÇAMENTO BASE ZERO ACFT SENECA V (PR-PME) /Meridian500 | AD2: ORÇAMENTO BASE ZERO ACFT SENECA V (PR-PME) /Meridian500 | AE2: ORÇAMENTO BASE ZERO ACFT SENECA V (PR-PME) /Meridian500
A3: Orçamento 2025/2026 | B3: Orçamento 2025/2026 | C3: Orçamento 2025/2026 | D3: Orçamento 2025/2026 | E3: Orçamento 2025/2026 | F3: Orçamento 2025/2026 | G3: Orçamento 2025/2026 | H3: Orçamento 2025/2026 | I3: Orçamento 2025/2026 | J3: Orçamento 2025/2026 | K3: Orçamento 2025/2026 | L3: Orçamento 2025/2026 | M3: Orçamento 2025/2026 | N3: Orçamento 2025/2026 | O3: Orçamento 2025/2026 | P3: Orçamento 2025/2026 | Q3: Orçamento 2025/2026 | X3: ITEM | Y3: QUANTIDADE | AA3: VALOR
D4: out | E4: Nov | F4: Dez | G4: jan | H4: Fev | I4: Mar | J4: Abr | K4: Mai | M4: Horas | O4: Total | P4: Valor unid | Q4: Total R$ | X4: Seguro reta | Y4: 1 | Z4: 767.88 | AA4: =Z4*Y4
A5: Aplicação Aerea | B5: Descrição | D5: Agroservice 1º fung soja 5.637 2º fung soja 5.637 3º fung soja 5.637 4º Fung soja 5.637 5°micro/ins 1º ins milho 3.678 2º ins milho 3.678 3º ins milho 3.678 4º fun milho 3.678 5º fun milho 3.678 6º ins milho 3.678 7° ins milho 8°ins milho Agroinvest= 5000 ha | E5: Agroservice 1º fung soja 5.637 2º fung soja 5.637 3º fung soja 5.637 4º Fung soja 5.637 5°micro/ins 1º ins milho 3.678 2º ins milho 3.678 3º ins milho 3.678 4º fun milho 3.678 5º fun milho 3.678 6º ins milho 3.678 7° ins milho 8°ins milho Agroinvest= 5000 ha | F5: Agroservice 1º fung soja 5.637 2º fung soja 5.637 3º fung soja 5.637 4º Fung soja 5.637 5°micro/ins 1º ins milho 3.678 2º ins milho 3.678 3º ins milho 3.678 4º fun milho 3.678 5º fun milho 3.678 6º ins milho 3.678 7° ins milho 8°ins milho Agroinvest= 5000 ha | G5: Agroservice algodão 22 aplicação inseticida total 5280 Há fugincida 6 aplicação total 1440Ha Agroinvest = 6000 há | H5: 3500 mix de cobertura pivõ 10 aplicações =1600 | I5: 3 aplicações inseticida Safrinha 1500 | L5: AGROSERVICE milho = 29424 soja=28.185 algodão=6.720 sorgo=1.500 pivô milho=1.600 AGROINVEST=11.000 TOTAL=78.429 | O5: 78429 | X5: Atendiemnto Angar Icaro (BSB) | Y5: 12 | Z5: 1500 | AA5: =Z5*Y5
A6: Air tractor B502 | B6: Area trabalhada | C6: Há liquido 20 | D6: 9600 | E6: 22548 | F6: 29933 | G6: 12608 | H6: 2240 | I6: 1500 | O6: =SUM(D6:N6) | X6: jeepson -Renovação assinatura garmim | Y6: 1 | Z6: 6400 | AA6: =Z6*Y6 | AD6: Valor aquisição Meridian | AE6: 3175000
A7: Air tractor B502 | B7: Area trabalhada | X7: Revisoes/manutençoes | Y7: 1 | Z7: 40000 | AA7: =Z7*Y7 | AD7: Agroservice 50% | AE7: =AE6/2
A8: Air tractor B502 | B8: Area trabalhada | C8: há solido | H8: 3500 | M8: 40/h | O8: =SUM(F8:J8) | P8: 500 | Q8: 20000 | X8: Angarage | Y8: 12 | Z8: 850 | AA8: =Z8*Y8
A9: Air tractor B502 | B9: Horas trabalhada | C9: Hora | D9: =SUM(D6:D7)/185 | E9: =SUM(E6:E7)/185 | F9: =SUM(F6:F7)/185 | G9: =SUM(G6:G7)/185 | H9: =SUM(H6:H7)/185 | I9: =SUM(I6:I7)/185 | J9: =J6/175 | O9: =SUM(D9:J9) | X9: Piloto | Y9: 13 | Z9: 9000 | AA9: =Z9*Y9
A10: Air tractor B502 | B10: Querosene | C10: Lt | D10: =220*D9 | E10: =220*E9 | F10: =220*F9 | G10: =220*G9 | H10: =220*H9 | I10: =220*I9 | O10: =SUM(D10:J10) | P10: 6 | Q10: =P10*O10 | X10: Combustivel (querosene) | Y10: 12 | Z10: 5625 | AA10: =Z10*Y10
A11: Air tractor B502 | B11: Oleo Motor/turbina | C11: Lt | D11: =D9/20 | E11: =E9/20 | F11: =F9/20 | G11: =G9/20 | H11: =H9/20 | I11: 0 | O11: =SUM(D11:J11) | P11: 60 | Q11: =P11*O11 | X11: Taxas Inframerica (pousos) + Decea (tarifa uso EP) | Y11: 12 | Z11: 920.84 | AA11: =Z11*Y11
A12: Air tractor B502 | B12: REVISÃO 100/Hr | O12: 1 | P12: 6380 | Q12: 6380 | Y12: Total | AA12: =SUM(AA4:AA11)
A13: Air tractor B502 | B13: REVISÃO 200/Hr | O13: 1 | P13: 1540 | Q13: 1540
A14: Air tractor B502 | B14: REVISÃO 300/Hr | O14: 1 | P14: 9350 | Q14: 9350
A15: Air tractor B502 | B15: TBO turbina | C15: Und | J15: 1 | O15: 1 | P15: 1070000 | Q15: =P15*O15/10
A16: Air tractor B502 | B16: IAM | C16: R$ | J16: 1 | O16: =SUM(D16:J16) | P16: 25000 | Q16: =P16*O16 | R16: Custo de peças durante as revisões de 100,200,300 horas
A17: Air tractor B502 | B17: Seguro reta | C17: R$ | J17: 1 | O17: =SUM(D17:J17) | P17: 600 | Q17: =P17*O17
A18: Air tractor B502 | B18: Mão de obra manutenção | C18: R$ | J18: 1 | O18: =SUM(D18:J18) | P18: 80000 | Q18: =P18*O18
A19: Air tractor B502 | B19: Peças revisão | C19: R$ | O19: 1 | P19: 50000 | Q19: =P19*O19
A20: Air tractor B502 | B20: Pneus dianteiro | C20: Und | D20: 2 | O20: =SUM(D20:J20) | P20: 7000 | Q20: =P20*O20
A21: Air tractor B502 | B21: Camara ar | C21: Und | D21: 2 | O21: =SUM(D21:J21) | P21: 1600 | Q21: =P21*O21 | R21: revisão efetuada safra 23-24 | S21: revisão efetuada safra 23-24 | T21: revisão efetuada safra 23-24
A22: Air tractor B502 | B22: Pneu bequilha | C22: Und | D22: 1 | O22: =SUM(D22:J22) | P22: 1200 | Q22: =P22*O22
A23: Air tractor B502 | B23: Camara bequilha | C23: Und | D23: 1 | O23: =SUM(D23:J23) | P23: 550 | Q23: =P23*O23
A24: Air tractor B502 | B24: Revisao pós safra | O24: 1 | P24: 150000 | Q24: =O24*P24
A25: Air tractor B502 | B25: Pastilha freio | C25: Und | F25: 12 | J25: 24 | O25: =SUM(D25:J25) | P25: 75 | Q25: =P25*O25
A26: Air tractor B502 | B26: Escova limpa sensor | C26: Und | E26: 1 | G26: 1 | O26: 3 | P26: 30 | Q26: 90
A27: Air tractor B502 | B27: Filtro ar o par | C27: Und | E27: 2 | F27: 2 | G27: 2 | O27: 6 | P27: 380 | Q27: =P27*O27
A28: Air tractor B502 | B28: Filtro combustivel | C28: Und | D28: 1 | F28: 1 | I28: 1 | O28: =SUM(D28:J28) | P28: 65 | Q28: =P28*O28
A29: Air tractor B502 | B29: Saco de estoupa | C29: Und | D29: 1 | O29: =SUM(D29:J29) | P29: 120 | Q29: =P29*O29
A30: Air tractor B502 | B30: Cera para brisa | C30: Und | D30: 1 | O30: =SUM(D30:J30) | P30: 230 | Q30: =P30*O30
A31: Air tractor B502 | B31: Reparos bomba solução | C31: und | D31: 2 | O31: 2 | P31: 375 | Q31: =P31*O31
A32: Air tractor B502 | B32: conjunto de bicos cp 11tt | C32: und | D32: 42 | O32: 42 | P32: 521.38 | Q32: =P32*O32
A33: Air tractor B502 | B33: bomba eólica | C33: und | D33: 1 | O33: 1 | P33: 7156.59 | Q33: =P33*O33
A34: Air tractor B502 | B34: funil inox duas curvas | C34: und | D34: 1 | O34: =SUM(D34:N34) | P34: 65 | Q34: =P34*O34
A35: Air tractor B502 | B35: Detergente neutro | C35: Und | D35: 36 | O35: =SUM(D35:J35) | P35: 4 | Q35: =P35*O35
A36: Acessorios de aplicação | B36: Mangueira 3 pol | C36: mt | D36: 20 | O36: =SUM(D36:J36) | P36: 75 | Q36: =P36*O36
A37: Acessorios de aplicação | B37: Engate rapido 3 Pol | C37: Und | D37: 4 | O37: =SUM(D37:J37) | P37: 160 | Q37: =P37*O37
A38: Acessorios de aplicação | B38: CADEADO | C38: Und | D38: 1 | O38: 1 | P38: 45 | Q38: 45
A39: Acessorios de aplicação | B39: Registro 3 pol | C39: Und | D39: 2 | O39: =SUM(D39:J39) | P39: 600 | Q39: =P39*O39
A40: Acessorios de aplicação | B40: Mangueira 3 pol flexivel | C40: Mt | D40: 30 | O40: =SUM(D40:J40) | P40: 60 | Q40: =P40*O40
...

Sheet Deprecisação 
A1: 10/17/2025 | B1: 10/17/2025 | C1: 10/17/2025 | D1: 10/17/2025 | E1: Agroinvest Ltda | F1: Agroinvest Ltda | G1: Agroinvest Ltda | H1: Agroinvest Ltda | I1: Agroinvest Ltda | J1: Agroinvest Ltda | K1: Agroinvest Ltda
A2: 2:04 PM | B2: 2:04 PM | C2: 2:04 PM | D2: 2:04 PM | E2: Agroinvest Ltda | F2: Agroinvest Ltda | G2: Agroinvest Ltda | H2: Agroinvest Ltda | I2: Agroinvest Ltda | J2: Agroinvest Ltda | K2: Agroinvest Ltda
A3: 2:04 PM | B3: 2:04 PM | C3: 2:04 PM | D3: 2:04 PM
A4: 2:04 PM | B4: 2:04 PM | C4: 2:04 PM | D4: 2:04 PM | E4: Fixed Asset Activity | F4: Fixed Asset Activity | G4: Fixed Asset Activity | H4: Fixed Asset Activity | I4: Fixed Asset Activity | J4: Fixed Asset Activity | K4: Fixed Asset Activity
E5: Fixed Asset Activity | F5: Fixed Asset Activity | G5: Fixed Asset Activity | H5: Fixed Asset Activity | I5: Fixed Asset Activity | J5: Fixed Asset Activity | K5: Fixed Asset Activity
